<?xml version="1.0"?>
<robot xmlns:xacro="http://www.ros.org/wiki/xacro" >

    <xacro:include filename="inertial_macros.xacro"/>

    <material name="white">
        <color rgba="1 1 1 1" />
    </material>

    <material name="orange">
        <color rgba="1 0.3 0.1 1"/>
    </material>

    <material name="blue">
        <color rgba="0.2 0.2 1 1"/>
    </material>

    <material name="black">
        <color rgba="0 0 0 1"/>
    </material>

    <!-- BASE LINK -->

    <link name="base_link">

    </link>


    <!-- CHASSIS LINK -->

    <joint name="chassis_joint" type="fixed">
        <parent link="base_link"/>
        <child link="chassis"/>
        <origin xyz="-0.150 0 0.016"/>
    </joint>

    <link name="chassis">
        <visual>
            <origin xyz="0.19 0 0.0625"/>
            <geometry>
                <box size="0.38 0.25 0.125"/>
            </geometry>
            <material name="white"/>
        </visual>
        <collision>
            <origin xyz="0.19 0 0.0625"/>
            <geometry>
                <box size="0.38 0.25 0.125"/>
            </geometry>
            <material name="white"/>
        </collision>
        <xacro:inertial_box mass="1.5" x="0.38" y="0.25" z="0.125">
            <origin xyz="0.15 0 0.075" rpy="0 0 0"/>
        </xacro:inertial_box>
    </link>
    
    <!-- LEFT WHEEL LINK -->

    <joint name="left_wheel_joint" type="continuous">
        <parent link="base_link"/>
        <child link="left_wheel"/>
        <origin xyz="0 0.125 0" rpy="-${pi/2} 0 0" />
        <axis xyz="0 0 1"/>
    </joint>

    <link name="left_wheel">
        <visual>
            <geometry>
                <cylinder radius="0.024" length="0.037"/>
            </geometry>
            <material name="blue"/>
        </visual>
        <collision>
            <geometry>
                <cylinder radius="0.024" length="0.037"/>
            </geometry>
        </collision>
        <xacro:inertial_cylinder mass="0.3" length="0.037" radius="0.024">
            <origin xyz="0 0 0" rpy="0 0 0"/>
        </xacro:inertial_cylinder>
    </link>

    <!-- RIGHT WHEEL LINK -->

    <joint name="right_wheel_joint" type="continuous">
        <parent link="base_link"/>
        <child link="right_wheel"/>
        <origin xyz="0 -0.125 0" rpy="${pi/2} 0 0" />
        <axis xyz="0 0 -1"/>
    </joint>

    <link name="right_wheel">
        <visual>
            <geometry>
                <cylinder radius="0.024" length="0.037"/>
            </geometry>
            <material name="blue"/>
        </visual>
        <collision>
            <geometry>
                <cylinder radius="0.024" length="0.037"/>
            </geometry>
        </collision>
        <xacro:inertial_cylinder mass="0.3" length="0.037" radius="0.024">
            <origin xyz="0 0 0" rpy="0 0 0"/>
        </xacro:inertial_cylinder>
    </link>

    <!-- CASTER WHEEL FRONT LINK -->

    <joint name="caster_wheel_joint_front" type="fixed">
        <parent link="chassis"/>
        <child link="caster_wheel_front"/>
        <origin xyz="0.38 0 0"/>
    </joint>


    <link name="caster_wheel_front">
        <visual>
            <geometry>
                <sphere radius="0.04"/>
            </geometry>
            <material name="black"/>
        </visual>
        <collision>
            <geometry>
                <sphere radius="0.04"/>
            </geometry>
        </collision>
        <xacro:inertial_sphere mass="0.1" radius="0.04">
            <origin xyz="0 0 0" rpy="0 0 0"/>
        </xacro:inertial_sphere>
    </link>

    <!-- CASTER WHEEL REAR LINK -->

    <joint name="caster_wheel_joint_rear" type="fixed">
        <parent link="chassis"/>
        <child link="caster_wheel_rear"/>
        <origin xyz="0.06 0 0"/>
    </joint>


    <link name="caster_wheel_rear">
        <visual>
            <geometry>
                <sphere radius="0.04"/>
            </geometry>
            <material name="black"/>
        </visual>
        <collision>
            <geometry>
                <sphere radius="0.04"/>
            </geometry>
        </collision>
        <xacro:inertial_sphere mass="0.1" radius="0.04">
            <origin xyz="0 0 0" rpy="0 0 0"/>
        </xacro:inertial_sphere>
    </link>

    <!-- SENSORS -->
    
    
</robot>